Workbook

Sheet Supuestos
A1: clave | B1: concepto | C1: unidad | D1: común | E1: optimista | F1: neutral | G1: pesimista | H1: fuente
A2: Fuente de cada supuesto: wiki/negocio/analisis-financiero.md. Clave bibliográfica = documento/biblio.bib.
A4: Horizonte, calendario y tasa
A5: horizonte | B5: Horizonte de evaluación | C5: años | D5: 5 | H5: Decisión de #45
A6: anio_0 | B6: Año calendario del año 0 | C6: año | D6: 2026 | H6: Supuesto propio
A7: meses_anio | B7: Meses por año | C7: meses | D7: 12 | H7: —
A8: anio_electoral | B8: Año 0 con elección nacional (1 = sí) | C8: 0/1 | D8: 0 | H8: ConvencionConstituyente1994, LaNacion2026
B9: Año 1 con elección nacional (1 = sí) | C9: 0/1 | D9: 1 | H9: ConvencionConstituyente1994, LaNacion2026
B10: Año 2 con elección nacional (1 = sí) | C10: 0/1 | D10: 0 | H10: ConvencionConstituyente1994, LaNacion2026
B11: Año 3 con elección nacional (1 = sí) | C11: 0/1 | D11: 1 | H11: ConvencionConstituyente1994, LaNacion2026
B12: Año 4 con elección nacional (1 = sí) | C12: 0/1 | D12: 0 | H12: ConvencionConstituyente1994, LaNacion2026
B13: Año 5 con elección nacional (1 = sí) | C13: 0/1 | D13: 1 | H13: ConvencionConstituyente1994, LaNacion2026
A14: tasa_libre_riesgo | B14: Bono del Tesoro de EE. UU. a 10 años | C14: % | D14: 0.0517 | H14: FederalReserve2026
A15: riesgo_pais | B15: Riesgo país de Argentina (EMBI, 628 pb) | C15: % | D15: 0.0628 | H15: Infobae2026
A16: prima_proyecto | B16: Prima por proyecto nuevo | C16: % | D16: 0.1355 | H16: Supuesto propio, Damodaran2010
A17: tasa_descuento | B17: Tasa de descuento | C17: % | D17: =tasa_libre_riesgo+riesgo_pais+prima_proyecto -> 0.25 | H17: Suma de componentes
A18: erp_maduro | B18: Prima de riesgo de un mercado maduro (contraste CAPM) | C18: % | D18: 0.0423 | H18: Damodaran2026
A19: crp_argentina | B19: Prima de riesgo país de Argentina (contraste CAPM) | C19: % | D19: 0.0971 | H19: Damodaran2026
A20: tasa_capm | B20: Tasa CAPM de contraste, con beta igual a 1 | C20: % | D20: =tasa_libre_riesgo+erp_maduro+crp_argentina -> 0.1911 | H20: Cálculo
A21: crecimiento_perpetuo | B21: Crecimiento a perpetuidad para el valor residual | C21: % | D21: 0.02 | H21: Supuesto propio, no mayor al crecimiento de largo plazo
A23: Recursos humanos
A24: sueldo_ars | B24: Sueldo bruto mensual, developer semi senior | C24: ARS/mes | D24: 2501629 | H24: Sysarmy2026
A25: tc_encuesta | B25: Tipo de cambio implícito de la encuesta | C25: ARS/USD | D25: 1397.88 | H25: Sysarmy2026
A26: sueldo_usd | B26: Sueldo bruto mensual en USD | C26: USD/mes | D26: =ROUND(sueldo_ars/tc_encuesta,0) -> 1790 | H26: Cálculo
A27: sueldos_por_anio | B27: Sueldos por año (12 + aguinaldo) | C27: sueldos | D27: 13 | H27: Supuesto propio
A28: ajuste_sueldo | B28: Ajuste anual del sueldo en USD | C28: % | D28: 0.05 | H28: Supuesto propio
A29: cargas_sociales | B29: Cargas sociales del empleador (18 % + obra social 6 % + ART 2 %) | C29: % | D29: 0.26 | H29: CongresoNacion2019; ART: supuesto propio
A30: meses_anio_0 | B30: Meses de desarrollo del trabajo en el año 0 (no se imputan al flujo) | C30: meses | D30: 10 | H30: Cronograma del PFI
A32: Impuestos y capital de trabajo
A33: alicuota_ganancias | B33: Impuesto a las ganancias, con quebrantos trasladables | C33: % | D33: 0.35 | H33: Simplificación indicada por la cátedra
A34: meses_cobro | B34: Plazo de cobro de los clientes B2B y B2G | C34: meses | D34: 2 | H34: Supuesto propio
A36: Inversión del año 0 (además del desarrollo)
A37: inv_infraestructura_0 | B37: Infraestructura durante el PFI: API y clasificador en Railway (13 USD/mes × 12) | C37: USD | D37: 156 | H37: Cap. 4, RNF-14; RailwayPrecios2026
A38: inv_dominio | B38: Dominio .com.ar, primer año (ARS 8.500) | C38: USD | D38: 5.5 | H38: NICArgentina2026
A39: inv_marca_inpi | B39: Solicitud de marca en el INPI, clases 9 y 42 (200 UMAPI) | C39: USD | D39: 53 | H39: INPI2026, INPIUmapi2026
A40: inv_legal | B40: Asesoría legal | C40: USD | D40: 1500 | H40: Supuesto propio
A42: Infraestructura y hosting (años 1 a 5)
A43: infra_base | B43: Base comercial: Railway Pro, con 20 USD de uso incluidos (API y clasificador, 13 USD/mes) | C43: USD/mes | D43: 20 | H43: Railway2026
A44: infra_escalado | B44: Uso adicional por cada bloque de usuarios activos (1 GB de memoria) | C44: USD/mes | D44: 10 | H44: Supuesto propio; tarifa RailwayPrecios2026
A45: ua_escalado | B45: Usuarios activos por bloque de escalado | C45: UA | D45: 10000 | H45: Supuesto propio
...

Sheet Resumen
A1: Indicador | B1: Optimista | C1: Neutral | D1: Pesimista
A2: VAN (USD) | B2: =Optimista!B74 -> 833353.48 | C2: =Neutral!B74 -> 63935.762 | D2: =Pesimista!B74 -> -94161.066
A3: TIR | B3: =Optimista!B75 -> 55.545393 | C3: =Neutral!B75 -> 0.72550446 | D3: =Pesimista!B75 -> no definida
A4: Payback simple (años) | B4: =Optimista!B76 -> 0.018458976 | C4: =Neutral!B76 -> 2.9321736 | D4: =Pesimista!B76 -> no se recupera
A5: Payback descontado (años) | B5: =Optimista!B77 -> 0.02307372 | C5: =Neutral!B77 -> 3.4622135 | D5: =Pesimista!B77 -> no se recupera
A6: Punto de equilibrio (clientes B2B) | B6: =Optimista!B80 -> 17 | C6: =Neutral!B80 -> 23 | D6: =Pesimista!B80 -> 21
A7: Ingreso medio por cliente B2B en el año 5 (USD) | B7: =Optimista!B79 -> 10781.443 | C7: =Neutral!B79 -> 8901.2048 | D7: =Pesimista!B79 -> 5600
A8: VAN con valor residual (USD) | B8: =Optimista!B78 -> 1609256.9 | C8: =Neutral!B78 -> 199501.17 | D8: =Pesimista!B78 -> -94161.066
A10: Mercado, a precios del escenario neutral (USD por año)
A11: TAM: todo el universo de organizaciones contrata | B11: =meses_anio*(u_medios_grandes*INDEX(precio_medios_grandes,1,2)+(u_medios_total-u_medios_grandes)*precio_medios_chicos+u_verificadores*precio_verificadores+u_universidades*precio_universidades+u_agencias*INDEX(precio_agencias,1,2))+u_organismos*INDEX(precio_organismos,1,2) -> 5024800
A12: SAM: organizaciones que el producto y el canal atienden | B12: =meses_anio*(u_medios_grandes*INDEX(precio_medios_grandes,1,2)+u_medios_chicos*precio_medios_chicos+u_verificadores*precio_verificadores+u_universidades*precio_universidades+u_agencias*INDEX(precio_agencias,1,2))+u_organismos*INDEX(precio_organismos,1,2) -> 4960000
A13: SOM: ingresos del año 5, escenario neutral | B13: =Neutral!G45 -> 369400
A15: Contraste para la defensa
A16: Valor de mercado de las horas de desarrollo del año 0, no imputado (USD) | B16: =meses_anio_0*sueldo_usd*(1+cargas_sociales)*sueldos_por_anio/meses_anio -> 24433.5
A17: Tasa CAPM de contraste | B17: =tasa_capm -> 0.1911
A19: Margen mensual por cliente a cuota llena (USD) | B19: Optimista | C19: Neutral | D19: Pesimista
A20: API intermedia: costo variable a cuota llena | B20: =cuota_intermedia*(1-INDEX(tasa_reuso,1,1))*INDEX(costo_analisis,1,1)*sens_costo_analisis -> 38.232 | C20: =cuota_intermedia*(1-INDEX(tasa_reuso,1,2))*INDEX(costo_analisis,1,2)*sens_costo_analisis -> 86.254 | D20: =cuota_intermedia*(1-INDEX(tasa_reuso,1,3))*INDEX(costo_analisis,1,3)*sens_costo_analisis -> 151.856
A21: API intermedia: margen a cuota llena | B21: =precio_medios_chicos*sens_precios-cuota_intermedia*(1-INDEX(tasa_reuso,1,1))*INDEX(costo_analisis,1,1)*sens_costo_analisis -> 161.768 | C21: =precio_medios_chicos*sens_precios-cuota_intermedia*(1-INDEX(tasa_reuso,1,2))*INDEX(costo_analisis,1,2)*sens_costo_analisis -> 113.746 | D21: =precio_medios_chicos*sens_precios-cuota_intermedia*(1-INDEX(tasa_reuso,1,3))*INDEX(costo_analisis,1,3)*sens_costo_analisis -> 48.144
A22: API superior: costo variable a cuota llena | B22: =cuota_superior*(1-INDEX(tasa_reuso,1,1))*INDEX(costo_analisis,1,1)*sens_costo_analisis -> 305.856 | C22: =cuota_superior*(1-INDEX(tasa_reuso,1,2))*INDEX(costo_analisis,1,2)*sens_costo_analisis -> 690.032 | D22: =cuota_superior*(1-INDEX(tasa_reuso,1,3))*INDEX(costo_analisis,1,3)*sens_costo_analisis -> 1214.848
A23: API superior: margen a cuota llena | B23: =INDEX(precio_medios_grandes,1,1)*sens_precios-cuota_superior*(1-INDEX(tasa_reuso,1,1))*INDEX(costo_analisis,1,1)*sens_costo_analisis -> 2694.144 | C23: =INDEX(precio_medios_grandes,1,2)*sens_precios-cuota_superior*(1-INDEX(tasa_reuso,1,2))*INDEX(costo_analisis,1,2)*sens_costo_analisis -> 1809.968 | D23: =INDEX(precio_medios_grandes,1,3)*sens_precios-cuota_superior*(1-INDEX(tasa_reuso,1,3))*INDEX(costo_analisis,1,3)*sens_costo_analisis -> 285.152
A25: Economía unitaria, escenario neutral (USD) | B25: Precio mensual | C25: Costo variable mensual | D25: Margen mensual | E25: Churn anual | F25: LTV | G25: LTV/CAC | H25: Payback del CAC (meses)
A26: CAC (USD por alta de suscripción) | B26: =SUM(Neutral!C50:G50)/(SUM(Neutral!C12:G12)+SUM(Neutral!C17:G17)+SUM(Neutral!C22:G22)+SUM(Neutral!C27:G27)+SUM(Neutral!C32:G32)) -> 740.74074
A27: Unitaria: Medios de gran porte | B27: =INDEX(precio_medios_grandes,1,2)*sens_precios -> 2500 | C27: =MIN(INDEX(consultas_ent_mes,1,2),cuota_superior)*(1-INDEX(tasa_reuso,1,2))*INDEX(costo_analisis,1,2)*sens_costo_analisis -> 690.032 | D27: =B27-C27 -> 1809.968 | E27: =INDEX(churn_medios_grandes,1,2) -> 0.15 | F27: =D27*meses_anio/E27 -> 144797.44 | G27: =F27/$B$26 -> 195.47654 | H27: =$B$26/D27 -> 0.40925626
A28: Unitaria: Medios socios de ADEPA (resto) | B28: =precio_medios_chicos*sens_precios -> 200 | C28: =MIN(INDEX(consultas_pro_mes,1,2),cuota_intermedia)*(1-INDEX(tasa_reuso,1,2))*INDEX(costo_analisis,1,2)*sens_costo_analisis -> 69.0032 | D28: =B28-C28 -> 130.9968 | E28: =INDEX(churn_medios_chicos,1,2) -> 0.2 | F28: =D28*meses_anio/E28 -> 7859.808 | G28: =F28/$B$26 -> 10.610741 | H28: =$B$26/D28 -> 5.6546476
A29: Unitaria: Verificadores | B29: =precio_verificadores*sens_precios -> 500 | C29: =MIN(INDEX(consultas_pro_mes,1,2),cuota_intermedia)*(1-INDEX(tasa_reuso,1,2))*INDEX(costo_analisis,1,2)*sens_costo_analisis -> 69.0032 | D29: =B29-C29 -> 430.9968 | E29: =INDEX(churn_verificadores,1,2) -> 0.1 | F29: =D29*meses_anio/E29 -> 51719.616 | G29: =F29/$B$26 -> 69.821482 | H29: =$B$26/D29 -> 1.7186688
A30: Unitaria: Universidades y observatorios | B30: =precio_universidades*sens_precios -> 100 | C30: =0*(1-INDEX(tasa_reuso,1,2))*INDEX(costo_analisis,1,2)*sens_costo_analisis -> 0 | D30: =B30-C30 -> 100 | E30: =INDEX(churn_universidades,1,2) -> 0.1 | F30: =D30*meses_anio/E30 -> 12000 | G30: =F30/$B$26 -> 16.2 | H30: =$B$26/D30 -> 7.4074074
A31: Unitaria: Agencias | B31: =INDEX(precio_agencias,1,2)*sens_precios -> 2500 | C31: =MIN(INDEX(consultas_ent_mes,1,2),cuota_superior)*(1-INDEX(tasa_reuso,1,2))*INDEX(costo_analisis,1,2)*sens_costo_analisis -> 690.032 | D31: =B31-C31 -> 1809.968 | E31: =INDEX(churn_agencias,1,2) -> 0.2 | F31: =D31*meses_anio/E31 -> 108598.08 | G31: =F31/$B$26 -> 146.60741 | H31: =$B$26/D31 -> 0.40925626

Sheet Optimista
A1: Escenario optimista (USD nominales; todo lo derivado es fórmula)
A2: Columna de escenario en Supuestos (1 = optimista, 2 = neutral, 3 = pesimista) | B2: 1
A3: Año | B3: =COLUMN()-2 -> 0 | C3: =COLUMN()-2 -> 1 | D3: =COLUMN()-2 -> 2 | E3: =COLUMN()-2 -> 3 | F3: =COLUMN()-2 -> 4 | G3: =COLUMN()-2 -> 5
A4: Año calendario | B4: =anio_0+B$3 -> 2026 | C4: =anio_0+C$3 -> 2027 | D4: =anio_0+D$3 -> 2028 | E4: =anio_0+E$3 -> 2029 | F4: =anio_0+F$3 -> 2030 | G4: =anio_0+G$3 -> 2031
A5: Año electoral (1 = sí) | B5: =INDEX(anio_electoral,B$3+1) -> 0 | C5: =INDEX(anio_electoral,C$3+1) -> 1 | D5: =INDEX(anio_electoral,D$3+1) -> 0 | E5: =INDEX(anio_electoral,E$3+1) -> 1 | F5: =INDEX(anio_electoral,F$3+1) -> 0 | G5: =INDEX(anio_electoral,G$3+1) -> 1
A6: Usuarios activos mensuales | C6: =INDEX(usuarios_activos,C$3,$B$2) -> 5000 | D6: =INDEX(usuarios_activos,D$3,$B$2) -> 20000 | E6: =INDEX(usuarios_activos,E$3,$B$2) -> 50000 | F6: =INDEX(usuarios_activos,F$3,$B$2) -> 100000 | G6: =INDEX(usuarios_activos,G$3,$B$2) -> 150000
A7: Ventas B2B habilitadas (1 = sí) | C7: =IF(C6>=ua_inicio_b2b,1,0) -> 1 | D7: =IF(D6>=ua_inicio_b2b,1,0) -> 1 | E7: =IF(E6>=ua_inicio_b2b,1,0) -> 1 | F7: =IF(F6>=ua_inicio_b2b,1,0) -> 1 | G7: =IF(G6>=ua_inicio_b2b,1,0) -> 1
A9: Clientes B2B
A10: Medios de gran porte: activos al inicio | C10: =N(B13) -> 0 | D10: =N(C13) -> 2 | E10: =N(D13) -> 4 | F10: =N(E13) -> 5 | G10: =N(F13) -> 5
A11: Medios de gran porte: bajas | C11: =ROUND(INDEX(churn_medios_grandes,1,$B$2)*C10,0) -> 0 | D11: =ROUND(INDEX(churn_medios_grandes,1,$B$2)*D10,0) -> 0 | E11: =ROUND(INDEX(churn_medios_grandes,1,$B$2)*E10,0) -> 0 | F11: =ROUND(INDEX(churn_medios_grandes,1,$B$2)*F10,0) -> 1 | G11: =ROUND(INDEX(churn_medios_grandes,1,$B$2)*G10,0) -> 1
A12: Medios de gran porte: altas | C12: =C7*ROUND(INDEX(capt_medios_grandes,1,$B$2)*sens_captacion*(u_medios_grandes-C10),0) -> 2 | D12: =D7*ROUND(INDEX(capt_medios_grandes,1,$B$2)*sens_captacion*(u_medios_grandes-D10),0) -> 2 | E12: =E7*ROUND(INDEX(capt_medios_grandes,1,$B$2)*sens_captacion*(u_medios_grandes-E10),0) -> 1 | F12: =F7*ROUND(INDEX(capt_medios_grandes,1,$B$2)*sens_captacion*(u_medios_grandes-F10),0) -> 1 | G12: =G7*ROUND(INDEX(capt_medios_grandes,1,$B$2)*sens_captacion*(u_medios_grandes-G10),0) -> 1
A13: Medios de gran porte: activos al cierre | C13: =C10+C12-C11 -> 2 | D13: =D10+D12-D11 -> 4 | E13: =E10+E12-E11 -> 5 | F13: =F10+F12-F11 -> 5 | G13: =G10+G12-G11 -> 5
A14: Medios de gran porte: promedio del año | C14: =(C10+C13)/2 -> 1 | D14: =(D10+D13)/2 -> 3 | E14: =(E10+E13)/2 -> 4.5 | F14: =(F10+F13)/2 -> 5 | G14: =(G10+G13)/2 -> 5
A15: Medios socios de ADEPA (resto): activos al inicio | C15: =N(B18) -> 0 | D15: =N(C18) -> 9 | E15: =N(D18) -> 16 | F15: =N(E18) -> 22 | G15: =N(F18) -> 26
A16: Medios socios de ADEPA (resto): bajas | C16: =ROUND(INDEX(churn_medios_chicos,1,$B$2)*C15,0) -> 0 | D16: =ROUND(INDEX(churn_medios_chicos,1,$B$2)*D15,0) -> 1 | E16: =ROUND(INDEX(churn_medios_chicos,1,$B$2)*E15,0) -> 2 | F16: =ROUND(INDEX(churn_medios_chicos,1,$B$2)*F15,0) -> 3 | G16: =ROUND(INDEX(churn_medios_chicos,1,$B$2)*G15,0) -> 4
A17: Medios socios de ADEPA (resto): altas | C17: =C7*ROUND(INDEX(capt_medios_chicos,1,$B$2)*sens_captacion*(u_medios_chicos-C15),0) -> 9 | D17: =D7*ROUND(INDEX(capt_medios_chicos,1,$B$2)*sens_captacion*(u_medios_chicos-D15),0) -> 8 | E17: =E7*ROUND(INDEX(capt_medios_chicos,1,$B$2)*sens_captacion*(u_medios_chicos-E15),0) -> 8 | F17: =F7*ROUND(INDEX(capt_medios_chicos,1,$B$2)*sens_captacion*(u_medios_chicos-F15),0) -> 7 | G17: =G7*ROUND(INDEX(capt_medios_chicos,1,$B$2)*sens_captacion*(u_medios_chicos-G15),0) -> 7
A18: Medios socios de ADEPA (resto): activos al cierre | C18: =C15+C17-C16 -> 9 | D18: =D15+D17-D16 -> 16 | E18: =E15+E17-E16 -> 22 | F18: =F15+F17-F16 -> 26 | G18: =G15+G17-G16 -> 29
A19: Medios socios de ADEPA (resto): promedio del año | C19: =(C15+C18)/2 -> 4.5 | D19: =(D15+D18)/2 -> 12.5 | E19: =(E15+E18)/2 -> 19 | F19: =(F15+F18)/2 -> 24 | G19: =(G15+G18)/2 -> 27.5
A20: Verificadores: activos al inicio | C20: =N(B23) -> 0 | D20: =N(C23) -> 1 | E20: =N(D23) -> 2 | F20: =N(E23) -> 2 | G20: =N(F23) -> 2
A21: Verificadores: bajas | C21: =ROUND(INDEX(churn_verificadores,1,$B$2)*C20,0) -> 0 | D21: =ROUND(INDEX(churn_verificadores,1,$B$2)*D20,0) -> 0 | E21: =ROUND(INDEX(churn_verificadores,1,$B$2)*E20,0) -> 0 | F21: =ROUND(INDEX(churn_verificadores,1,$B$2)*F20,0) -> 0 | G21: =ROUND(INDEX(churn_verificadores,1,$B$2)*G20,0) -> 0
A22: Verificadores: altas | C22: =C7*ROUND(INDEX(capt_verificadores,1,$B$2)*sens_captacion*(u_verificadores-C20),0) -> 1 | D22: =D7*ROUND(INDEX(capt_verificadores,1,$B$2)*sens_captacion*(u_verificadores-D20),0) -> 1 | E22: =E7*ROUND(INDEX(capt_verificadores,1,$B$2)*sens_captacion*(u_verificadores-E20),0) -> 0 | F22: =F7*ROUND(INDEX(capt_verificadores,1,$B$2)*sens_captacion*(u_verificadores-F20),0) -> 0 | G22: =G7*ROUND(INDEX(capt_verificadores,1,$B$2)*sens_captacion*(u_verificadores-G20),0) -> 0
A23: Verificadores: activos al cierre | C23: =C20+C22-C21 -> 1 | D23: =D20+D22-D21 -> 2 | E23: =E20+E22-E21 -> 2 | F23: =F20+F22-F21 -> 2 | G23: =G20+G22-G21 -> 2
A24: Verificadores: promedio del año | C24: =(C20+C23)/2 -> 0.5 | D24: =(D20+D23)/2 -> 1.5 | E24: =(E20+E23)/2 -> 2 | F24: =(F20+F23)/2 -> 2 | G24: =(G20+G23)/2 -> 2
A25: Universidades y observatorios: activos al inicio | C25: =N(B28) -> 0 | D25: =N(C28) -> 12 | E25: =N(D28) -> 22 | F25: =N(E28) -> 31 | G25: =N(F28) -> 38
A26: Universidades y observatorios: bajas | C26: =ROUND(INDEX(churn_universidades,1,$B$2)*C25,0) -> 0 | D26: =ROUND(INDEX(churn_universidades,1,$B$2)*D25,0) -> 1 | E26: =ROUND(INDEX(churn_universidades,1,$B$2)*E25,0) -> 1 | F26: =ROUND(INDEX(churn_universidades,1,$B$2)*F25,0) -> 2 | G26: =ROUND(INDEX(churn_universidades,1,$B$2)*G25,0) -> 2
A27: Universidades y observatorios: altas | C27: =C7*ROUND(INDEX(capt_universidades,1,$B$2)*sens_captacion*(u_universidades-C25),0) -> 12 | D27: =D7*ROUND(INDEX(capt_universidades,1,$B$2)*sens_captacion*(u_universidades-D25),0) -> 11 | E27: =E7*ROUND(INDEX(capt_universidades,1,$B$2)*sens_captacion*(u_universidades-E25),0) -> 10 | F27: =F7*ROUND(INDEX(capt_universidades,1,$B$2)*sens_captacion*(u_universidades-F25),0) -> 9 | G27: =G7*ROUND(INDEX(capt_universidades,1,$B$2)*sens_captacion*(u_universidades-G25),0) -> 9
A28: Universidades y observatorios: activos al cierre | C28: =C25+C27-C26 -> 12 | D28: =D25+D27-D26 -> 22 | E28: =E25+E27-E26 -> 31 | F28: =F25+F27-F26 -> 38 | G28: =G25+G27-G26 -> 45
A29: Universidades y observatorios: promedio del año | C29: =(C25+C28)/2 -> 6 | D29: =(D25+D28)/2 -> 17 | E29: =(E25+E28)/2 -> 26.5 | F29: =(F25+F28)/2 -> 34.5 | G29: =(G25+G28)/2 -> 41.5
A30: Agencias: activos al inicio | C30: =N(B33) -> 0 | D30: =N(C33) -> 6 | E30: =N(D33) -> 11 | F30: =N(E33) -> 14 | G30: =N(F33) -> 17
A31: Agencias: bajas | C31: =ROUND(INDEX(churn_agencias,1,$B$2)*C30,0) -> 0 | D31: =ROUND(INDEX(churn_agencias,1,$B$2)*D30,0) -> 1 | E31: =ROUND(INDEX(churn_agencias,1,$B$2)*E30,0) -> 2 | F31: =ROUND(INDEX(churn_agencias,1,$B$2)*F30,0) -> 2 | G31: =ROUND(INDEX(churn_agencias,1,$B$2)*G30,0) -> 3
A32: Agencias: altas | C32: =C7*ROUND(INDEX(capt_agencias,1,$B$2)*sens_captacion*(u_agencias-C30),0) -> 6 | D32: =D7*ROUND(INDEX(capt_agencias,1,$B$2)*sens_captacion*(u_agencias-D30),0) -> 6 | E32: =E7*ROUND(INDEX(capt_agencias,1,$B$2)*sens_captacion*(u_agencias-E30),0) -> 5 | F32: =F7*ROUND(INDEX(capt_agencias,1,$B$2)*sens_captacion*(u_agencias-F30),0) -> 5 | G32: =G7*ROUND(INDEX(capt_agencias,1,$B$2)*sens_captacion*(u_agencias-G30),0) -> 5
A33: Agencias: activos al cierre | C33: =C30+C32-C31 -> 6 | D33: =D30+D32-D31 -> 11 | E33: =E30+E32-E31 -> 14 | F33: =F30+F32-F31 -> 17 | G33: =G30+G32-G31 -> 19
A34: Agencias: promedio del año | C34: =(C30+C33)/2 -> 3 | D34: =(D30+D33)/2 -> 8.5 | E34: =(E30+E33)/2 -> 12.5 | F34: =(F30+F33)/2 -> 15.5 | G34: =(G30+G33)/2 -> 18
A35: Organismos y ONG: contratos | C35: =C5*C7*ROUND(INDEX(capt_organismos,1,$B$2)*sens_captacion*u_organismos,0) -> 3 | D35: =D5*D7*ROUND(INDEX(capt_organismos,1,$B$2)*sens_captacion*u_organismos,0) -> 0 | E35: =E5*E7*ROUND(INDEX(capt_organismos,1,$B$2)*sens_captacion*u_organismos,0) -> 3 | F35: =F5*F7*ROUND(INDEX(capt_organismos,1,$B$2)*sens_captacion*u_organismos,0) -> 0 | G35: =G5*G7*ROUND(INDEX(capt_organismos,1,$B$2)*sens_captacion*u_organismos,0) -> 3
A36: Clientes B2B (promedio del año, con contratos) | C36: =C14+C19+C24+C29+C34+C35 -> 18 | D36: =D14+D19+D24+D29+D34+D35 -> 42.5 | E36: =E14+E19+E24+E29+E34+E35 -> 67.5 | F36: =F14+F19+F24+F29+F34+F35 -> 81 | G36: =G14+G19+G24+G29+G34+G35 -> 97
A38: Ingresos por producto
A39: Ingresos: API nivel superior (Medios de gran porte) | C39: =C14*INDEX(precio_medios_grandes,1,$B$2)*sens_precios*meses_anio -> 36000 | D39: =D14*INDEX(precio_medios_grandes,1,$B$2)*sens_precios*meses_anio -> 108000 | E39: =E14*INDEX(precio_medios_grandes,1,$B$2)*sens_precios*meses_anio -> 162000 | F39: =F14*INDEX(precio_medios_grandes,1,$B$2)*sens_precios*meses_anio -> 180000 | G39: =G14*INDEX(precio_medios_grandes,1,$B$2)*sens_precios*meses_anio -> 180000
A40: Ingresos: API nivel intermedio (Medios socios de ADEPA (resto)) | C40: =C19*precio_medios_chicos*sens_precios*meses_anio -> 10800 | D40: =D19*precio_medios_chicos*sens_precios*meses_anio -> 30000 | E40: =E19*precio_medios_chicos*sens_precios*meses_anio -> 45600 | F40: =F19*precio_medios_chicos*sens_precios*meses_anio -> 57600 | G40: =G19*precio_medios_chicos*sens_precios*meses_anio -> 66000
A41: Ingresos: panel de tendencias y API intermedia (Verificadores) | C41: =C24*precio_verificadores*sens_precios*meses_anio -> 3000 | D41: =D24*precio_verificadores*sens_precios*meses_anio -> 9000 | E41: =E24*precio_verificadores*sens_precios*meses_anio -> 12000 | F41: =F24*precio_verificadores*sens_precios*meses_anio -> 12000 | G41: =G24*precio_verificadores*sens_precios*meses_anio -> 12000
A42: Ingresos: acceso histórico (Universidades y observatorios) | C42: =C29*precio_universidades*sens_precios*meses_anio -> 7200 | D42: =D29*precio_universidades*sens_precios*meses_anio -> 20400 | E42: =E29*precio_universidades*sens_precios*meses_anio -> 31800 | F42: =F29*precio_universidades*sens_precios*meses_anio -> 41400 | G42: =G29*precio_universidades*sens_precios*meses_anio -> 49800
...

Sheet Neutral
A1: Escenario neutral (USD nominales; todo lo derivado es fórmula)
A2: Columna de escenario en Supuestos (1 = optimista, 2 = neutral, 3 = pesimista) | B2: 2
A3: Año | B3: =COLUMN()-2 -> 0 | C3: =COLUMN()-2 -> 1 | D3: =COLUMN()-2 -> 2 | E3: =COLUMN()-2 -> 3 | F3: =COLUMN()-2 -> 4 | G3: =COLUMN()-2 -> 5
A4: Año calendario | B4: =anio_0+B$3 -> 2026 | C4: =anio_0+C$3 -> 2027 | D4: =anio_0+D$3 -> 2028 | E4: =anio_0+E$3 -> 2029 | F4: =anio_0+F$3 -> 2030 | G4: =anio_0+G$3 -> 2031
A5: Año electoral (1 = sí) | B5: =INDEX(anio_electoral,B$3+1) -> 0 | C5: =INDEX(anio_electoral,C$3+1) -> 1 | D5: =INDEX(anio_electoral,D$3+1) -> 0 | E5: =INDEX(anio_electoral,E$3+1) -> 1 | F5: =INDEX(anio_electoral,F$3+1) -> 0 | G5: =INDEX(anio_electoral,G$3+1) -> 1
A6: Usuarios activos mensuales | C6: =INDEX(usuarios_activos,C$3,$B$2) -> 2000 | D6: =INDEX(usuarios_activos,D$3,$B$2) -> 8000 | E6: =INDEX(usuarios_activos,E$3,$B$2) -> 20000 | F6: =INDEX(usuarios_activos,F$3,$B$2) -> 40000 | G6: =INDEX(usuarios_activos,G$3,$B$2) -> 60000
A7: Ventas B2B habilitadas (1 = sí) | C7: =IF(C6>=ua_inicio_b2b,1,0) -> 0 | D7: =IF(D6>=ua_inicio_b2b,1,0) -> 1 | E7: =IF(E6>=ua_inicio_b2b,1,0) -> 1 | F7: =IF(F6>=ua_inicio_b2b,1,0) -> 1 | G7: =IF(G6>=ua_inicio_b2b,1,0) -> 1
A9: Clientes B2B
A10: Medios de gran porte: activos al inicio | C10: =N(B13) -> 0 | D10: =N(C13) -> 0 | E10: =N(D13) -> 1 | F10: =N(E13) -> 2 | G10: =N(F13) -> 3
A11: Medios de gran porte: bajas | C11: =ROUND(INDEX(churn_medios_grandes,1,$B$2)*C10,0) -> 0 | D11: =ROUND(INDEX(churn_medios_grandes,1,$B$2)*D10,0) -> 0 | E11: =ROUND(INDEX(churn_medios_grandes,1,$B$2)*E10,0) -> 0 | F11: =ROUND(INDEX(churn_medios_grandes,1,$B$2)*F10,0) -> 0 | G11: =ROUND(INDEX(churn_medios_grandes,1,$B$2)*G10,0) -> 0
A12: Medios de gran porte: altas | C12: =C7*ROUND(INDEX(capt_medios_grandes,1,$B$2)*sens_captacion*(u_medios_grandes-C10),0) -> 0 | D12: =D7*ROUND(INDEX(capt_medios_grandes,1,$B$2)*sens_captacion*(u_medios_grandes-D10),0) -> 1 | E12: =E7*ROUND(INDEX(capt_medios_grandes,1,$B$2)*sens_captacion*(u_medios_grandes-E10),0) -> 1 | F12: =F7*ROUND(INDEX(capt_medios_grandes,1,$B$2)*sens_captacion*(u_medios_grandes-F10),0) -> 1 | G12: =G7*ROUND(INDEX(capt_medios_grandes,1,$B$2)*sens_captacion*(u_medios_grandes-G10),0) -> 1
A13: Medios de gran porte: activos al cierre | C13: =C10+C12-C11 -> 0 | D13: =D10+D12-D11 -> 1 | E13: =E10+E12-E11 -> 2 | F13: =F10+F12-F11 -> 3 | G13: =G10+G12-G11 -> 4
A14: Medios de gran porte: promedio del año | C14: =(C10+C13)/2 -> 0 | D14: =(D10+D13)/2 -> 0.5 | E14: =(E10+E13)/2 -> 1.5 | F14: =(F10+F13)/2 -> 2.5 | G14: =(G10+G13)/2 -> 3.5
A15: Medios socios de ADEPA (resto): activos al inicio | C15: =N(B18) -> 0 | D15: =N(C18) -> 0 | E15: =N(D18) -> 5 | F15: =N(E18) -> 8 | G15: =N(F18) -> 10
A16: Medios socios de ADEPA (resto): bajas | C16: =ROUND(INDEX(churn_medios_chicos,1,$B$2)*C15,0) -> 0 | D16: =ROUND(INDEX(churn_medios_chicos,1,$B$2)*D15,0) -> 0 | E16: =ROUND(INDEX(churn_medios_chicos,1,$B$2)*E15,0) -> 1 | F16: =ROUND(INDEX(churn_medios_chicos,1,$B$2)*F15,0) -> 2 | G16: =ROUND(INDEX(churn_medios_chicos,1,$B$2)*G15,0) -> 2
A17: Medios socios de ADEPA (resto): altas | C17: =C7*ROUND(INDEX(capt_medios_chicos,1,$B$2)*sens_captacion*(u_medios_chicos-C15),0) -> 0 | D17: =D7*ROUND(INDEX(capt_medios_chicos,1,$B$2)*sens_captacion*(u_medios_chicos-D15),0) -> 5 | E17: =E7*ROUND(INDEX(capt_medios_chicos,1,$B$2)*sens_captacion*(u_medios_chicos-E15),0) -> 4 | F17: =F7*ROUND(INDEX(capt_medios_chicos,1,$B$2)*sens_captacion*(u_medios_chicos-F15),0) -> 4 | G17: =G7*ROUND(INDEX(capt_medios_chicos,1,$B$2)*sens_captacion*(u_medios_chicos-G15),0) -> 4
A18: Medios socios de ADEPA (resto): activos al cierre | C18: =C15+C17-C16 -> 0 | D18: =D15+D17-D16 -> 5 | E18: =E15+E17-E16 -> 8 | F18: =F15+F17-F16 -> 10 | G18: =G15+G17-G16 -> 12
A19: Medios socios de ADEPA (resto): promedio del año | C19: =(C15+C18)/2 -> 0 | D19: =(D15+D18)/2 -> 2.5 | E19: =(E15+E18)/2 -> 6.5 | F19: =(F15+F18)/2 -> 9 | G19: =(G15+G18)/2 -> 11
A20: Verificadores: activos al inicio | C20: =N(B23) -> 0 | D20: =N(C23) -> 0 | E20: =N(D23) -> 1 | F20: =N(E23) -> 2 | G20: =N(F23) -> 2
A21: Verificadores: bajas | C21: =ROUND(INDEX(churn_verificadores,1,$B$2)*C20,0) -> 0 | D21: =ROUND(INDEX(churn_verificadores,1,$B$2)*D20,0) -> 0 | E21: =ROUND(INDEX(churn_verificadores,1,$B$2)*E20,0) -> 0 | F21: =ROUND(INDEX(churn_verificadores,1,$B$2)*F20,0) -> 0 | G21: =ROUND(INDEX(churn_verificadores,1,$B$2)*G20,0) -> 0
A22: Verificadores: altas | C22: =C7*ROUND(INDEX(capt_verificadores,1,$B$2)*sens_captacion*(u_verificadores-C20),0) -> 0 | D22: =D7*ROUND(INDEX(capt_verificadores,1,$B$2)*sens_captacion*(u_verificadores-D20),0) -> 1 | E22: =E7*ROUND(INDEX(capt_verificadores,1,$B$2)*sens_captacion*(u_verificadores-E20),0) -> 1 | F22: =F7*ROUND(INDEX(capt_verificadores,1,$B$2)*sens_captacion*(u_verificadores-F20),0) -> 0 | G22: =G7*ROUND(INDEX(capt_verificadores,1,$B$2)*sens_captacion*(u_verificadores-G20),0) -> 0
A23: Verificadores: activos al cierre | C23: =C20+C22-C21 -> 0 | D23: =D20+D22-D21 -> 1 | E23: =E20+E22-E21 -> 2 | F23: =F20+F22-F21 -> 2 | G23: =G20+G22-G21 -> 2
A24: Verificadores: promedio del año | C24: =(C20+C23)/2 -> 0 | D24: =(D20+D23)/2 -> 0.5 | E24: =(E20+E23)/2 -> 1.5 | F24: =(F20+F23)/2 -> 2 | G24: =(G20+G23)/2 -> 2
A25: Universidades y observatorios: activos al inicio | C25: =N(B28) -> 0 | D25: =N(C28) -> 0 | E25: =N(D28) -> 6 | F25: =N(E28) -> 11 | G25: =N(F28) -> 16
A26: Universidades y observatorios: bajas | C26: =ROUND(INDEX(churn_universidades,1,$B$2)*C25,0) -> 0 | D26: =ROUND(INDEX(churn_universidades,1,$B$2)*D25,0) -> 0 | E26: =ROUND(INDEX(churn_universidades,1,$B$2)*E25,0) -> 1 | F26: =ROUND(INDEX(churn_universidades,1,$B$2)*F25,0) -> 1 | G26: =ROUND(INDEX(churn_universidades,1,$B$2)*G25,0) -> 2
A27: Universidades y observatorios: altas | C27: =C7*ROUND(INDEX(capt_universidades,1,$B$2)*sens_captacion*(u_universidades-C25),0) -> 0 | D27: =D7*ROUND(INDEX(capt_universidades,1,$B$2)*sens_captacion*(u_universidades-D25),0) -> 6 | E27: =E7*ROUND(INDEX(capt_universidades,1,$B$2)*sens_captacion*(u_universidades-E25),0) -> 6 | F27: =F7*ROUND(INDEX(capt_universidades,1,$B$2)*sens_captacion*(u_universidades-F25),0) -> 6 | G27: =G7*ROUND(INDEX(capt_universidades,1,$B$2)*sens_captacion*(u_universidades-G25),0) -> 5
A28: Universidades y observatorios: activos al cierre | C28: =C25+C27-C26 -> 0 | D28: =D25+D27-D26 -> 6 | E28: =E25+E27-E26 -> 11 | F28: =F25+F27-F26 -> 16 | G28: =G25+G27-G26 -> 19
A29: Universidades y observatorios: promedio del año | C29: =(C25+C28)/2 -> 0 | D29: =(D25+D28)/2 -> 3 | E29: =(E25+E28)/2 -> 8.5 | F29: =(F25+F28)/2 -> 13.5 | G29: =(G25+G28)/2 -> 17.5
A30: Agencias: activos al inicio | C30: =N(B33) -> 0 | D30: =N(C33) -> 0 | E30: =N(D33) -> 2 | F30: =N(E33) -> 4 | G30: =N(F33) -> 5
A31: Agencias: bajas | C31: =ROUND(INDEX(churn_agencias,1,$B$2)*C30,0) -> 0 | D31: =ROUND(INDEX(churn_agencias,1,$B$2)*D30,0) -> 0 | E31: =ROUND(INDEX(churn_agencias,1,$B$2)*E30,0) -> 0 | F31: =ROUND(INDEX(churn_agencias,1,$B$2)*F30,0) -> 1 | G31: =ROUND(INDEX(churn_agencias,1,$B$2)*G30,0) -> 1
A32: Agencias: altas | C32: =C7*ROUND(INDEX(capt_agencias,1,$B$2)*sens_captacion*(u_agencias-C30),0) -> 0 | D32: =D7*ROUND(INDEX(capt_agencias,1,$B$2)*sens_captacion*(u_agencias-D30),0) -> 2 | E32: =E7*ROUND(INDEX(capt_agencias,1,$B$2)*sens_captacion*(u_agencias-E30),0) -> 2 | F32: =F7*ROUND(INDEX(capt_agencias,1,$B$2)*sens_captacion*(u_agencias-F30),0) -> 2 | G32: =G7*ROUND(INDEX(capt_agencias,1,$B$2)*sens_captacion*(u_agencias-G30),0) -> 2
A33: Agencias: activos al cierre | C33: =C30+C32-C31 -> 0 | D33: =D30+D32-D31 -> 2 | E33: =E30+E32-E31 -> 4 | F33: =F30+F32-F31 -> 5 | G33: =G30+G32-G31 -> 6
A34: Agencias: promedio del año | C34: =(C30+C33)/2 -> 0 | D34: =(D30+D33)/2 -> 1 | E34: =(E30+E33)/2 -> 3 | F34: =(F30+F33)/2 -> 4.5 | G34: =(G30+G33)/2 -> 5.5
A35: Organismos y ONG: contratos | C35: =C5*C7*ROUND(INDEX(capt_organismos,1,$B$2)*sens_captacion*u_organismos,0) -> 0 | D35: =D5*D7*ROUND(INDEX(capt_organismos,1,$B$2)*sens_captacion*u_organismos,0) -> 0 | E35: =E5*E7*ROUND(INDEX(capt_organismos,1,$B$2)*sens_captacion*u_organismos,0) -> 2 | F35: =F5*F7*ROUND(INDEX(capt_organismos,1,$B$2)*sens_captacion*u_organismos,0) -> 0 | G35: =G5*G7*ROUND(INDEX(capt_organismos,1,$B$2)*sens_captacion*u_organismos,0) -> 2
A36: Clientes B2B (promedio del año, con contratos) | C36: =C14+C19+C24+C29+C34+C35 -> 0 | D36: =D14+D19+D24+D29+D34+D35 -> 7.5 | E36: =E14+E19+E24+E29+E34+E35 -> 23 | F36: =F14+F19+F24+F29+F34+F35 -> 31.5 | G36: =G14+G19+G24+G29+G34+G35 -> 41.5
A38: Ingresos por producto
A39: Ingresos: API nivel superior (Medios de gran porte) | C39: =C14*INDEX(precio_medios_grandes,1,$B$2)*sens_precios*meses_anio -> 0 | D39: =D14*INDEX(precio_medios_grandes,1,$B$2)*sens_precios*meses_anio -> 15000 | E39: =E14*INDEX(precio_medios_grandes,1,$B$2)*sens_precios*meses_anio -> 45000 | F39: =F14*INDEX(precio_medios_grandes,1,$B$2)*sens_precios*meses_anio -> 75000 | G39: =G14*INDEX(precio_medios_grandes,1,$B$2)*sens_precios*meses_anio -> 105000
A40: Ingresos: API nivel intermedio (Medios socios de ADEPA (resto)) | C40: =C19*precio_medios_chicos*sens_precios*meses_anio -> 0 | D40: =D19*precio_medios_chicos*sens_precios*meses_anio -> 6000 | E40: =E19*precio_medios_chicos*sens_precios*meses_anio -> 15600 | F40: =F19*precio_medios_chicos*sens_precios*meses_anio -> 21600 | G40: =G19*precio_medios_chicos*sens_precios*meses_anio -> 26400
A41: Ingresos: panel de tendencias y API intermedia (Verificadores) | C41: =C24*precio_verificadores*sens_precios*meses_anio -> 0 | D41: =D24*precio_verificadores*sens_precios*meses_anio -> 3000 | E41: =E24*precio_verificadores*sens_precios*meses_anio -> 9000 | F41: =F24*precio_verificadores*sens_precios*meses_anio -> 12000 | G41: =G24*precio_verificadores*sens_precios*meses_anio -> 12000
A42: Ingresos: acceso histórico (Universidades y observatorios) | C42: =C29*precio_universidades*sens_precios*meses_anio -> 0 | D42: =D29*precio_universidades*sens_precios*meses_anio -> 3600 | E42: =E29*precio_universidades*sens_precios*meses_anio -> 10200 | F42: =F29*precio_universidades*sens_precios*meses_anio -> 16200 | G42: =G29*precio_universidades*sens_precios*meses_anio -> 21000
...

Sheet Pesimista
A1: Escenario pesimista (USD nominales; todo lo derivado es fórmula)
A2: Columna de escenario en Supuestos (1 = optimista, 2 = neutral, 3 = pesimista) | B2: 3
A3: Año | B3: =COLUMN()-2 -> 0 | C3: =COLUMN()-2 -> 1 | D3: =COLUMN()-2 -> 2 | E3: =COLUMN()-2 -> 3 | F3: =COLUMN()-2 -> 4 | G3: =COLUMN()-2 -> 5
A4: Año calendario | B4: =anio_0+B$3 -> 2026 | C4: =anio_0+C$3 -> 2027 | D4: =anio_0+D$3 -> 2028 | E4: =anio_0+E$3 -> 2029 | F4: =anio_0+F$3 -> 2030 | G4: =anio_0+G$3 -> 2031
A5: Año electoral (1 = sí) | B5: =INDEX(anio_electoral,B$3+1) -> 0 | C5: =INDEX(anio_electoral,C$3+1) -> 1 | D5: =INDEX(anio_electoral,D$3+1) -> 0 | E5: =INDEX(anio_electoral,E$3+1) -> 1 | F5: =INDEX(anio_electoral,F$3+1) -> 0 | G5: =INDEX(anio_electoral,G$3+1) -> 1
A6: Usuarios activos mensuales | C6: =INDEX(usuarios_activos,C$3,$B$2) -> 500 | D6: =INDEX(usuarios_activos,D$3,$B$2) -> 2000 | E6: =INDEX(usuarios_activos,E$3,$B$2) -> 5000 | F6: =INDEX(usuarios_activos,F$3,$B$2) -> 8000 | G6: =INDEX(usuarios_activos,G$3,$B$2) -> 10000
A7: Ventas B2B habilitadas (1 = sí) | C7: =IF(C6>=ua_inicio_b2b,1,0) -> 0 | D7: =IF(D6>=ua_inicio_b2b,1,0) -> 0 | E7: =IF(E6>=ua_inicio_b2b,1,0) -> 1 | F7: =IF(F6>=ua_inicio_b2b,1,0) -> 1 | G7: =IF(G6>=ua_inicio_b2b,1,0) -> 1
A9: Clientes B2B
A10: Medios de gran porte: activos al inicio | C10: =N(B13) -> 0 | D10: =N(C13) -> 0 | E10: =N(D13) -> 0 | F10: =N(E13) -> 1 | G10: =N(F13) -> 1
A11: Medios de gran porte: bajas | C11: =ROUND(INDEX(churn_medios_grandes,1,$B$2)*C10,0) -> 0 | D11: =ROUND(INDEX(churn_medios_grandes,1,$B$2)*D10,0) -> 0 | E11: =ROUND(INDEX(churn_medios_grandes,1,$B$2)*E10,0) -> 0 | F11: =ROUND(INDEX(churn_medios_grandes,1,$B$2)*F10,0) -> 0 | G11: =ROUND(INDEX(churn_medios_grandes,1,$B$2)*G10,0) -> 0
A12: Medios de gran porte: altas | C12: =C7*ROUND(INDEX(capt_medios_grandes,1,$B$2)*sens_captacion*(u_medios_grandes-C10),0) -> 0 | D12: =D7*ROUND(INDEX(capt_medios_grandes,1,$B$2)*sens_captacion*(u_medios_grandes-D10),0) -> 0 | E12: =E7*ROUND(INDEX(capt_medios_grandes,1,$B$2)*sens_captacion*(u_medios_grandes-E10),0) -> 1 | F12: =F7*ROUND(INDEX(capt_medios_grandes,1,$B$2)*sens_captacion*(u_medios_grandes-F10),0) -> 0 | G12: =G7*ROUND(INDEX(capt_medios_grandes,1,$B$2)*sens_captacion*(u_medios_grandes-G10),0) -> 0
A13: Medios de gran porte: activos al cierre | C13: =C10+C12-C11 -> 0 | D13: =D10+D12-D11 -> 0 | E13: =E10+E12-E11 -> 1 | F13: =F10+F12-F11 -> 1 | G13: =G10+G12-G11 -> 1
A14: Medios de gran porte: promedio del año | C14: =(C10+C13)/2 -> 0 | D14: =(D10+D13)/2 -> 0 | E14: =(E10+E13)/2 -> 0.5 | F14: =(F10+F13)/2 -> 1 | G14: =(G10+G13)/2 -> 1
A15: Medios socios de ADEPA (resto): activos al inicio | C15: =N(B18) -> 0 | D15: =N(C18) -> 0 | E15: =N(D18) -> 0 | F15: =N(E18) -> 2 | G15: =N(F18) -> 3
A16: Medios socios de ADEPA (resto): bajas | C16: =ROUND(INDEX(churn_medios_chicos,1,$B$2)*C15,0) -> 0 | D16: =ROUND(INDEX(churn_medios_chicos,1,$B$2)*D15,0) -> 0 | E16: =ROUND(INDEX(churn_medios_chicos,1,$B$2)*E15,0) -> 0 | F16: =ROUND(INDEX(churn_medios_chicos,1,$B$2)*F15,0) -> 1 | G16: =ROUND(INDEX(churn_medios_chicos,1,$B$2)*G15,0) -> 1
A17: Medios socios de ADEPA (resto): altas | C17: =C7*ROUND(INDEX(capt_medios_chicos,1,$B$2)*sens_captacion*(u_medios_chicos-C15),0) -> 0 | D17: =D7*ROUND(INDEX(capt_medios_chicos,1,$B$2)*sens_captacion*(u_medios_chicos-D15),0) -> 0 | E17: =E7*ROUND(INDEX(capt_medios_chicos,1,$B$2)*sens_captacion*(u_medios_chicos-E15),0) -> 2 | F17: =F7*ROUND(INDEX(capt_medios_chicos,1,$B$2)*sens_captacion*(u_medios_chicos-F15),0) -> 2 | G17: =G7*ROUND(INDEX(capt_medios_chicos,1,$B$2)*sens_captacion*(u_medios_chicos-G15),0) -> 2
A18: Medios socios de ADEPA (resto): activos al cierre | C18: =C15+C17-C16 -> 0 | D18: =D15+D17-D16 -> 0 | E18: =E15+E17-E16 -> 2 | F18: =F15+F17-F16 -> 3 | G18: =G15+G17-G16 -> 4
A19: Medios socios de ADEPA (resto): promedio del año | C19: =(C15+C18)/2 -> 0 | D19: =(D15+D18)/2 -> 0 | E19: =(E15+E18)/2 -> 1 | F19: =(F15+F18)/2 -> 2.5 | G19: =(G15+G18)/2 -> 3.5
A20: Verificadores: activos al inicio | C20: =N(B23) -> 0 | D20: =N(C23) -> 0 | E20: =N(D23) -> 0 | F20: =N(E23) -> 1 | G20: =N(F23) -> 1
A21: Verificadores: bajas | C21: =ROUND(INDEX(churn_verificadores,1,$B$2)*C20,0) -> 0 | D21: =ROUND(INDEX(churn_verificadores,1,$B$2)*D20,0) -> 0 | E21: =ROUND(INDEX(churn_verificadores,1,$B$2)*E20,0) -> 0 | F21: =ROUND(INDEX(churn_verificadores,1,$B$2)*F20,0) -> 0 | G21: =ROUND(INDEX(churn_verificadores,1,$B$2)*G20,0) -> 0
A22: Verificadores: altas | C22: =C7*ROUND(INDEX(capt_verificadores,1,$B$2)*sens_captacion*(u_verificadores-C20),0) -> 0 | D22: =D7*ROUND(INDEX(capt_verificadores,1,$B$2)*sens_captacion*(u_verificadores-D20),0) -> 0 | E22: =E7*ROUND(INDEX(capt_verificadores,1,$B$2)*sens_captacion*(u_verificadores-E20),0) -> 1 | F22: =F7*ROUND(INDEX(capt_verificadores,1,$B$2)*sens_captacion*(u_verificadores-F20),0) -> 0 | G22: =G7*ROUND(INDEX(capt_verificadores,1,$B$2)*sens_captacion*(u_verificadores-G20),0) -> 0
A23: Verificadores: activos al cierre | C23: =C20+C22-C21 -> 0 | D23: =D20+D22-D21 -> 0 | E23: =E20+E22-E21 -> 1 | F23: =F20+F22-F21 -> 1 | G23: =G20+G22-G21 -> 1
A24: Verificadores: promedio del año | C24: =(C20+C23)/2 -> 0 | D24: =(D20+D23)/2 -> 0 | E24: =(E20+E23)/2 -> 0.5 | F24: =(F20+F23)/2 -> 1 | G24: =(G20+G23)/2 -> 1
A25: Universidades y observatorios: activos al inicio | C25: =N(B28) -> 0 | D25: =N(C28) -> 0 | E25: =N(D28) -> 0 | F25: =N(E28) -> 3 | G25: =N(F28) -> 6
A26: Universidades y observatorios: bajas | C26: =ROUND(INDEX(churn_universidades,1,$B$2)*C25,0) -> 0 | D26: =ROUND(INDEX(churn_universidades,1,$B$2)*D25,0) -> 0 | E26: =ROUND(INDEX(churn_universidades,1,$B$2)*E25,0) -> 0 | F26: =ROUND(INDEX(churn_universidades,1,$B$2)*F25,0) -> 0 | G26: =ROUND(INDEX(churn_universidades,1,$B$2)*G25,0) -> 1
A27: Universidades y observatorios: altas | C27: =C7*ROUND(INDEX(capt_universidades,1,$B$2)*sens_captacion*(u_universidades-C25),0) -> 0 | D27: =D7*ROUND(INDEX(capt_universidades,1,$B$2)*sens_captacion*(u_universidades-D25),0) -> 0 | E27: =E7*ROUND(INDEX(capt_universidades,1,$B$2)*sens_captacion*(u_universidades-E25),0) -> 3 | F27: =F7*ROUND(INDEX(capt_universidades,1,$B$2)*sens_captacion*(u_universidades-F25),0) -> 3 | G27: =G7*ROUND(INDEX(capt_universidades,1,$B$2)*sens_captacion*(u_universidades-G25),0) -> 3
A28: Universidades y observatorios: activos al cierre | C28: =C25+C27-C26 -> 0 | D28: =D25+D27-D26 -> 0 | E28: =E25+E27-E26 -> 3 | F28: =F25+F27-F26 -> 6 | G28: =G25+G27-G26 -> 8
A29: Universidades y observatorios: promedio del año | C29: =(C25+C28)/2 -> 0 | D29: =(D25+D28)/2 -> 0 | E29: =(E25+E28)/2 -> 1.5 | F29: =(F25+F28)/2 -> 4.5 | G29: =(G25+G28)/2 -> 7
A30: Agencias: activos al inicio | C30: =N(B33) -> 0 | D30: =N(C33) -> 0 | E30: =N(D33) -> 0 | F30: =N(E33) -> 1 | G30: =N(F33) -> 2
A31: Agencias: bajas | C31: =ROUND(INDEX(churn_agencias,1,$B$2)*C30,0) -> 0 | D31: =ROUND(INDEX(churn_agencias,1,$B$2)*D30,0) -> 0 | E31: =ROUND(INDEX(churn_agencias,1,$B$2)*E30,0) -> 0 | F31: =ROUND(INDEX(churn_agencias,1,$B$2)*F30,0) -> 0 | G31: =ROUND(INDEX(churn_agencias,1,$B$2)*G30,0) -> 1
A32: Agencias: altas | C32: =C7*ROUND(INDEX(capt_agencias,1,$B$2)*sens_captacion*(u_agencias-C30),0) -> 0 | D32: =D7*ROUND(INDEX(capt_agencias,1,$B$2)*sens_captacion*(u_agencias-D30),0) -> 0 | E32: =E7*ROUND(INDEX(capt_agencias,1,$B$2)*sens_captacion*(u_agencias-E30),0) -> 1 | F32: =F7*ROUND(INDEX(capt_agencias,1,$B$2)*sens_captacion*(u_agencias-F30),0) -> 1 | G32: =G7*ROUND(INDEX(capt_agencias,1,$B$2)*sens_captacion*(u_agencias-G30),0) -> 1
A33: Agencias: activos al cierre | C33: =C30+C32-C31 -> 0 | D33: =D30+D32-D31 -> 0 | E33: =E30+E32-E31 -> 1 | F33: =F30+F32-F31 -> 2 | G33: =G30+G32-G31 -> 2
A34: Agencias: promedio del año | C34: =(C30+C33)/2 -> 0 | D34: =(D30+D33)/2 -> 0 | E34: =(E30+E33)/2 -> 0.5 | F34: =(F30+F33)/2 -> 1.5 | G34: =(G30+G33)/2 -> 2
A35: Organismos y ONG: contratos | C35: =C5*C7*ROUND(INDEX(capt_organismos,1,$B$2)*sens_captacion*u_organismos,0) -> 0 | D35: =D5*D7*ROUND(INDEX(capt_organismos,1,$B$2)*sens_captacion*u_organismos,0) -> 0 | E35: =E5*E7*ROUND(INDEX(capt_organismos,1,$B$2)*sens_captacion*u_organismos,0) -> 1 | F35: =F5*F7*ROUND(INDEX(capt_organismos,1,$B$2)*sens_captacion*u_organismos,0) -> 0 | G35: =G5*G7*ROUND(INDEX(capt_organismos,1,$B$2)*sens_captacion*u_organismos,0) -> 1
A36: Clientes B2B (promedio del año, con contratos) | C36: =C14+C19+C24+C29+C34+C35 -> 0 | D36: =D14+D19+D24+D29+D34+D35 -> 0 | E36: =E14+E19+E24+E29+E34+E35 -> 5 | F36: =F14+F19+F24+F29+F34+F35 -> 10.5 | G36: =G14+G19+G24+G29+G34+G35 -> 15.5
A38: Ingresos por producto
A39: Ingresos: API nivel superior (Medios de gran porte) | C39: =C14*INDEX(precio_medios_grandes,1,$B$2)*sens_precios*meses_anio -> 0 | D39: =D14*INDEX(precio_medios_grandes,1,$B$2)*sens_precios*meses_anio -> 0 | E39: =E14*INDEX(precio_medios_grandes,1,$B$2)*sens_precios*meses_anio -> 9000 | F39: =F14*INDEX(precio_medios_grandes,1,$B$2)*sens_precios*meses_anio -> 18000 | G39: =G14*INDEX(precio_medios_grandes,1,$B$2)*sens_precios*meses_anio -> 18000
A40: Ingresos: API nivel intermedio (Medios socios de ADEPA (resto)) | C40: =C19*precio_medios_chicos*sens_precios*meses_anio -> 0 | D40: =D19*precio_medios_chicos*sens_precios*meses_anio -> 0 | E40: =E19*precio_medios_chicos*sens_precios*meses_anio -> 2400 | F40: =F19*precio_medios_chicos*sens_precios*meses_anio -> 6000 | G40: =G19*precio_medios_chicos*sens_precios*meses_anio -> 8400
A41: Ingresos: panel de tendencias y API intermedia (Verificadores) | C41: =C24*precio_verificadores*sens_precios*meses_anio -> 0 | D41: =D24*precio_verificadores*sens_precios*meses_anio -> 0 | E41: =E24*precio_verificadores*sens_precios*meses_anio -> 3000 | F41: =F24*precio_verificadores*sens_precios*meses_anio -> 6000 | G41: =G24*precio_verificadores*sens_precios*meses_anio -> 6000
A42: Ingresos: acceso histórico (Universidades y observatorios) | C42: =C29*precio_universidades*sens_precios*meses_anio -> 0 | D42: =D29*precio_universidades*sens_precios*meses_anio -> 0 | E42: =E29*precio_universidades*sens_precios*meses_anio -> 1800 | F42: =F29*precio_universidades*sens_precios*meses_anio -> 5400 | G42: =G29*precio_universidades*sens_precios*meses_anio -> 8400
...
